Workbook
Name címek: 'Filmösszesítő'!$A$2:$A$18

Sheet Filmösszesítő
A1: Cím | B1: Játékidő (perc) | C1: Blokk | D1: Link | E1: Év | F1: Műfaj | G1: Leírás | H1: Sorszám
A2: 1435MM | B2: 20 | C2: Ident | D2: https://youtu.be/mrjREvSq28A | E2: 2016 | F2: Rövidfilm | G2: A világ vasútjainak több mint 50%-a 1435 mm-es nyomtávolságú. Nehéz egy külön esszé megnyitása nélkül ennél bővebben beszélni erről a műről. A Nocturnal Dog történetének egyik legfontosabb darabja a 1435MM, amely három szereplőt követ végig, akik sorsa összefonódik valahol végtelenben a feloldódás és eltűnés élménye által kísérve. A képek és a montázs embert próbáló, a hangulata kísérleti, de ez volt az első film, amely megragadta a műhely nehezen megragadható, de határozottan kitapintható identitását. | H2: 3
A3: Phish | B3: 7.75 | C3: Fordulatok | D3: https://youtu.be/dLq1gBb8lSc | E3: 2016 | F3: Misztikus | G3: Az első filmünk, amely a később bejáratott 48 órás filmpályázatra készült. A műfaj "mystery" címkével lett ellátva, szerepeltetnünk kellett egy halat a műben, és az "it will never fly" mondatnak el kellett valamilyen formában hangoznia. A történet egy rongyos gyerekcsoportról szól, akik ritualisztikus eszközökkel sikeresen véghez visznek valamit, ami a tudomány eszközeivel lehetetlennek bizonyul. | H3: 2
A4: Ördögszekér | B4: 25 | C4: Sötét oldal | D4: https://youtu.be/DZnKJDzESfI | E4: 2025 | F4: Rövidfilm | G4: Rita, Csaba és gyermekük Márk egy csodálatos közös vakációra készültek. Egy rossz kanyar és hibás útvonalválasztás azonban más irányba tereli az utazásukat, és egy országút menti társulat szállásánál kötnek ki. Szerencsére pont ma este játszák újra a világraszóló bábelőadásukat. | H4: 6
A5: Morzsi | B5: 2.63 | C5: Ident | D5: https://youtu.be/byx36iFVp2k | E5: 2016 | F5: Műhelyfilm | G5: A pincében anya és apa nagy rendetlenséggel találkozik. A család kutyája, Morzsi, elpusztul. Ezt a két eseményt köti össze ez az igen korai, klasszikus Nocturnal Dog alkotás. | H5: 5
A6: A varázsló halála | B6: 1.98 | C6: Ident | D6: https://youtu.be/srPUdQ6Il7o | E6: 2016 | F6: Dráma | G6: Egy testvérpár idősebb tagja kockázatos lépésre szánta el magát. Szerencsésen hazatért, de vajon minden marad a régiben, vagy örökre megváltozik az életük? Csáth Géza művének semmi köze a filmhez, viszont a Jalan Jalan zenei víziója itt fejti ki először a hatását az alkotásainkra. | H6: 9
A7: The Minimum Clearance Outline | B7: 8 | C7: Fordulatok | D7: https://youtu.be/nK5TWRSkJrQ | E7: 2017 | F7: Road movie | G7: Az általunk frekventált (ma már nem létező) 48 órás filmpályázat short listre került alkotása. Műfaja road movie, de mindenféle jármű nélkül. A filmben egy Dorothy jellegű karaktert követhetünk végig, ahogy egy tükörvilágban maga mellé gyűjtve hasonló sorsú útitársakat végül kimásznak a feledés és elveszettség síkjából. | H7: 5
A8: Fényszennyezés | B8: 5.65 | C8: Sötét oldal | D8: https://youtu.be/UCVhZ09MsD4 | E8: 2017 | F8: Rövidfilm | G8: Valami zajlik odakint. Egy csoportnyi gyerek ez elől menekült egy pincehelyiségbe. Vajon örökre csapdába kerültek, vagy megtalálják egyedül innen a kiutat? | H8: 4
A9: Három fehér ló | B9: 3.96 | C9: Projektek | D9: https://youtu.be/fF1MVz1zWrE | E9: 2018 | F9: Rövidfilm | G9: Két barát összeül sakkozni és iszogatni. Ekkor furcsa dolgok történnek. | H9: 2
A10: Kenopsia, opia, lachesism | B10: 5.92 | C10: Projektek | D10: https://youtu.be/Bs1tHvCRx8E | E10: 2018 | F10: Etűd | G10: Három szót választottunk, amik bonyolult érzéseket egy szóval írnak le. Kenopsia: egy érzés, ami akkor fog el minket, amikor egy olyan helyen járunk, ami most kihalt, ám a legtöbbször állandó nyüzsgésben látjuk. Opia: amikor a másik szemébe nézünk és egy egyszerre érződik behatoló gesztusnak és egyszerre törékenyek leszünk tőle. Lachesism: amikor titokban arra vágyunk, hogy átéljünk egy katasztrófát, pusztán, hogy túlélhessük. Kísérleti film Philip Glass méltán híres Koyaanisquatsi darabjára. | H10: 3
A11: Mr A, Mr K, a Pápa, Izom Tibor és az elnyomottak | B11: 5.2 | C11: Projektek | D11: https://youtu.be/opjXJhNPBO8 | E11: 2018 | F11: Kísérleti film | G11: Az emberi személyiség komplex dinamikák együtthatásában létezik. A film arra kísérlet, hogy megmutassa, hogy léteznek együtt különböző erők egy személyben. | H11: 4
A12: How to Make a Remake | B12: 14.37 | C12: Ident | D12: https://youtu.be/Fg-T8T7Tr5I | E12: 2018 | F12: Werkfilm | G12: A How To Make A Remake című film a 2018-as (akkor még) „bicós-mozis” táborban készült Remake (vagy néha tévesen: Remix) című nyári alkotásunk werkje. A film, amelyről ez a „hogyan készült?” stílusú munka szól, és amely nem került be a fesztiválprogramunkba, egy kevésbé közönségbarát mű visszaemlékezésről, alternatív valóságokról, kapcsolatokról és barátságról. Ádám sokszor jellemzi úgy a filmet, mint jó példa arra, amikor a folyamat jobb volt, mint maga az eredmény. A Remake rövid szinopszisa segíthet megérteni a werket: a táborozók 2018-ban üzeneteket kaptak egy baljós alternatív jövőből, amelyben a már kialakult veszélyt kizárólag a „vörös kutya” megmentésével lehet elkerülni, így üzenetet kell küldeni a múltba. | H12: 2
A13: Da Capo | B13: 5 | C13: Projektek | D13: https://youtu.be/JpRKm48n0n0?si=bVzJQbK98ZJ70QqI | E13: 2018 | F13: Etűd | G13: Mozart Requiemének megírásával kapcsolatban több párhuzamos városi legenda is létezik a köztudatban. A BFZ 2018-as "Lásd, amit hallasz" pályázatára készülő alkotásunk a zeneszerző utolsó szimfóniájának mitológiájáról emlékezik meg az első szimfóniája által vezetve. | H13: 7
... A18: Akherón ...és mi lett a pandával? | B18: 12 | C18: Ident | D18: https://youtu.be/_qTjQ7OeDrc | E18: 2021 | F18: Kísérleti film | G18: Hősünk testvérét elrabolták. A nyomok az alvilág legmélyebb bugyraiba vezetnek. Az Akherón - És a pandával mi lett? díjat nyert a 2021-es diákfilmszemlén. | H18: 8
A19: Aeronautika a 21. században | B19: 6.75 | D19: https://youtu.be/SUxI2YRGRnU | E19: 2016
A20: Praedo | B20: 0.6 | C20: Ident | D20: https://youtu.be/4OTwHdkkoIo | E20: 2021 | F20: Reklám | G20: Egy háztartásvezető élete nem könnyű. Ehhez nehéz bármi mást hozzáfűzni. Egyike a rengeteg stílusgyakorlatának a Nocturnal Dog filmműhelynek. | H20: 1
A21: Asomik | B21: 0.72 | C21: Fordulatok | D21: https://youtu.be/s1KhAeIctOw | E21: 2021 | F21: Reklám | G21: A szentgyőzőházai bányákból származó összetevők közismerten magas folttisztítóhatással rendelkezik. Ez a reklám a helybeli üzemekben készült Asomik mosószert mutatja be. Nekem beválik! | H21: 1
A22: Silence in Bjordall | B22: 1.05 | C22: Projektek | D22: https://youtu.be/QQkATp3ZrNE | E22: 2021 | F22: Trailer | G22: A finn fjordok közelében egy szürke kisváros éli mindennapjait egészen addig, amíg rejtélyes körülmények között nem válik gyilkosság áldozatává Judi. A rejtélyt felgöngyölíteni azonban csupán egy olyan ember képes, aki már rég visszavonult a bűnüldözéstől... Sigmund Vestarsson leghíresebb sorozatának főcímét láthatjuk. | H22: 1
A23: Piroska és a Farkas | B23: 16.78 | C23: Sötét oldal | D23: https://youtu.be/oOY_ZimZMC0 | E23: 2019 | F23: Rövidfilm/ Kísérleti film | G23: Közismert mese, talán a világ legismertebbje. Mi is feldolgoztuk, különböző ötleteket, stílusokat vegyítve a történettel. | H23: 5
A24: Aratás | B24: 30.28 | C24: Fordulatok | D24: https://youtu.be/k5C0P4FN7WQ | E24: 2022 | F24: Rövidfilm | G24: Négy mezőgazdasággal foglalkozó család gyerekei egy tanyán találják magukat. Ezt a helyet valami misztikus erő miatt nem tudják elhagyni, így csapdába kerültek. Egy nap Misire, az egyik legidősebb gyermekre holtan találnak. Ez felborítja az összeverődött családok közötti időleges békét. | H24: 4
A25: Ki ez a sok művész? | B25: 25.8 | C25: Fordulatok | D25: https://youtu.be/093OOQEkEfU | E25: 2023 | F25: Rövidfilm | G25: Az Újhegyi Waldorf Gimnázium színjátszószakkörének résztvevőit a diákszínjátszó fesztivál után elrabolják, és arra kényszerítik őket a fogvatartók, hogy folytassák az évekkel ezelőtt a műsorról levett kedvenc francia szappanoperájukat. A gyerekek végül egyetlen lehetőséget látnak arra, hogy értelmetlenné tegyék további fogvatartásukat. | H25: 3
A26: Greetings from Bjordall | B26: 1.07 | C26: Sötét oldal | D26: https://youtu.be/dgyIO9-bp0g | E26: 2021 | F26: Trailer | G26: Nyomozó? Drogdíler? Bűnöző? Olaf Guntersson főszereplésével a 2010-es évek közepén megalkották a finnek az északi régió talán egyik legismertebb, legszeretettebb sitcomját. Ennek a főcímét nézhetjük most végig. | H26: 1
A27: Jószándék | B27: 5.5 | C27: Projektek | D27: https://www.youtube.com/watch?v=NwJ8VgWiHeU | E27: 2024 | F27: Etűd | G27: 18 éven aluliaknak nem ajánlott. Egy nevelőintézetben nevelkedő gyermek fiatal felnőttként visszatér a már bezárt intézetbe, hogy szembenézzen a múltjával. Filmetűd Arvo Pärt Fratres című darabjára. | H27: 6
A28: Kiterítenek úgy is... | B28: 5.66 | C28: Ident | D28: https://www.youtube.com/watch?v=bBO8fy1W-3A | E28: 2024 | F28: Etűd | G28: Tan Dun Buddha Passion című alkotásának egy tételére készült 2024 nyarán Magyarszéken ez a filmetűd. Elsődlegesen Ádám munkája, amely a „Kádár dilemmája” anekdotára és morális dilemmára adott válaszként került megfogalmazásra. A film két iteráción keresztül mutatja be egy fausti alku, vagy egy tiltott gyümölcs körüli döntésopciókat. Az örök élet és örök tudás vajon elhozza-e a végtelen boldogságot az ember számára? | H28: 4
A29: Kezdetben volt a tett | B29: 3.76 | C29: Fordulatok | D29: https://youtu.be/0PxBSRa3yVs | E29: 2016 | F29: Etűd | G29: Az első hivatalosan is pályázatra leadott alkotása a Nocturnal Dog filmműhelynek: a BFZ 2016-os "Lásd, amit hallasz" pályázatára Sosztakovics Hamlet-szvitjére készítettük ezt az alkotást, amely egy Faust-történetet tár a nézők elé különféle kísérleti mozgóképes eszközökkel. | H29: 6
A30: Holnap | B30: 12.1 | C30: Sötét oldal | D30: https://youtu.be/OgBC-vPL0W8 | E30: 2024 | F30: Horror | G30: A világot megrázta a dél-jemeni parazita futótűzként terjedő és mutálódott változata. Ez az organizmus a központi idegrendszer éhséggel kapcsolatos részeit támadta meg, így minden fertőzött egyén kétségbeesetten keresi és zabálja fel az elé kerülő tápanyagforrásokat. Akit azonban a parazita nem észlel zabálónak, rögtön megfertőzi. Emberek egy kisebb csoportja sikeresen tudott kisebb, zárt kolóniákban életben maradni úgy, hogy "majszolóknak" tettették magukat, ezzel elkerülve a parazitafertőzést. Egy ideig. A paranoia azonban egy ilyen világban végzetes lehet. | H30: 3
A31: 4 szoba | B31: 10 | C31: Projektek | D31: TBA | E31: 2025 | F31: Kísérleti film | G31: Friss rezidens pszichiáter érkezik a klinikára. A fiatal orvosnak fel kell tűrnie az ingujját és munkához kell látnia, hiszen ezeket a klienseket egyáltalán nem könnyű kezelni. | H31: 5
A32: Drámaország | B32: 24.37 | D32: https://youtu.be/xOJwczfvYmg | E32: 2021 | F32: Rövidfilm | G32: A Drámaország nevű tábor évek óta sikerrel készíti fel a leendő színészpalántákat a nehéz színiiskolákra és a színpadi életre. Aki ilyen nehéz pályára vágyik, jól teszi, ha megragadja ezeket a lehetőségeket, ahol nagynevű tanároktól lesheti el a mesterség fogásait és közben még jól is érzi magát. Csakhogy a Drámaország nevű táborban a tanárok inkább álságosak, nagyképűek, kihasználják a gyermekek igyekezetét és kiszolgáltatottságát. A közelmúlt híreiből ismerős lehet a képlet. Viszont ebben a történetben a gyerekek a saját kezükbe veszik a sorsukat.

Sheet Programösszesítő
A1: Programpont | B1: Időtartam (perc) | C1: T+ | D1: Kezdés | E1: Vége
A2: Köszöntő | B2: 10 | C2: =0+B2 -> 10 | D2: 0.41666667 | E2: =TIME(10,0,0) + B2/1440 -> 0.42361111
A3: Ident (Nagy Márk?) | B3: =SUM('Ident (Ádám)'!C:C) -> 71.32 | C3: =C2+B3 -> 81.32 | D3: =E2 -> 0.42361111 | E3: =D3+B3/1440 -> 0.47313889
A4: Beszélgetés | B4: 20 | C4: =C3+B4 -> 101.32 | D4: =E3 -> 0.47313889 | E4: =D4+B4/1440 -> 0.48702778
A5: Szünet | B5: 15 | C5: =C4+B5 -> 116.32 | D5: =E4 -> 0.48702778 | E5: =D5+B5/1440 -> 0.49744444
A6: Fordulatok (Nagy Márk?) | B6: =SUM('Fordulatok (Ricsi)'!C:C) -> 76.31 | C6: =C4+B6 -> 177.63 | D6: =E5 -> 0.49744444 | E6: =D6+B6/1440 -> 0.5504375
A7: Beszélgetés | B7: 20 | C7: =C6+B7 -> 197.63 | D7: =E6 -> 0.5504375 | E7: =D7+B7/1440 -> 0.56432639
A8: Szünet | B8: 45 | C8: =C7+B8 -> 242.63 | D8: =E7 -> 0.56432639 | E8: =D8+B8/1440 -> 0.59557639
A9: Projektek (Kurdics Zoli?) | B9: =SUM('Projektek (Matyi)'!C:C) -> 66.25 | C9: =C8+B9 -> 308.88 | D9: =E8 -> 0.59557639 | E9: =D9+B9/1440 -> 0.64158333
A10: Beszélgetés | B10: 20 | C10: =C9+B10 -> 328.88 | D10: =E9 -> 0.64158333 | E10: =D10+B10/1440 -> 0.65547222
A11: Szünet | B11: 15 | C11: =C10+B11 -> 343.88 | D11: =E10 -> 0.65547222 | E11: =D11+B11/1440 -> 0.66588889
A12: Sötét oldal (Bak Marci?) | B12: =SUM('Sötét oldal (Marci)'!C:C) -> 64.03 | C12: =C10+B12 -> 392.91 | D12: =E11 -> 0.66588889 | E12: =D12+B12/1440 -> 0.71035417
A13: Beszélgetés | B13: 20 | C13: =C12+B13 -> 412.91 | D13: =E12 -> 0.71035417 | E13: =D13+B13/1440 -> 0.72424306
A14: Zárás | B14: 15 | C14: =C13+B14 -> 427.91 | D14: =E13 -> 0.72424306 | E14: =D14+B14/1440 -> 0.73465972
A17: RENDELKEZÉSRE ÁLLÓ IDŐ: | B17: 480
A18: ALLOKÁLT IDŐ: | B18: =SUM(Programösszesítő[Időtartam (perc)]) -> 457.91
A19: MARADÉK IDŐ: | B19: =B17-B18 -> 22.09

Sheet Ident (Ádám)
A1: Sorrend | B1: Cím | C1: Játékidő | D1: Link | E1: Év | F1: Újrarenderelve és mentve
A2: 1 | B2: Praedo | C2: =IFERROR(VLOOKUP(B2, 'Filmösszesítő'!A:E, 2, FALSE), "") -> 0.6 | D2: =IFERROR(VLOOKUP(B2, 'Filmösszesítő'!A:E, 4, FALSE), "") -> https://youtu.be/4OTwHdkkoIo | E2: =IFERROR(VLOOKUP(B2, 'Filmösszesítő'!A:E, 5, FALSE), "") -> 2021 | F2: TRUE
A3: 2 | B3: How to Make a Remake | C3: =IFERROR(VLOOKUP(B3, 'Filmösszesítő'!A:E, 2, FALSE), "") -> 14.37 | D3: =IFERROR(VLOOKUP(B3, 'Filmösszesítő'!A:E, 4, FALSE), "") -> https://youtu.be/Fg-T8T7Tr5I | E3: =IFERROR(VLOOKUP(B3, 'Filmösszesítő'!A:E, 5, FALSE), "") -> 2018 | F3: TRUE
A4: 3 | B4: 1435MM | C4: =IFERROR(VLOOKUP(B4, 'Filmösszesítő'!A:E, 2, FALSE), "") -> 20 | D4: =IFERROR(VLOOKUP(B4, 'Filmösszesítő'!A:E, 4, FALSE), "") -> https://youtu.be/mrjREvSq28A | E4: =IFERROR(VLOOKUP(B4, 'Filmösszesítő'!A:E, 5, FALSE), "") -> 2016 | F4: TRUE
A5: 4 | B5: Kiterítenek úgy is... | C5: =IFERROR(VLOOKUP(B5, 'Filmösszesítő'!A:E, 2, FALSE), "") -> 5.66 | D5: =IFERROR(VLOOKUP(B5, 'Filmösszesítő'!A:E, 4, FALSE), "") -> https://www.youtube.com/watch?v=bBO8fy1W-3A | E5: =IFERROR(VLOOKUP(B5, 'Filmösszesítő'!A:E, 5, FALSE), "") -> 2024 | F5: TRUE
A6: 5 | B6: Morzsi | C6: =IFERROR(VLOOKUP(B6, 'Filmösszesítő'!A:E, 2, FALSE), "") -> 2.63 | D6: =IFERROR(VLOOKUP(B6, 'Filmösszesítő'!A:E, 4, FALSE), "") -> https://youtu.be/byx36iFVp2k | E6: =IFERROR(VLOOKUP(B6, 'Filmösszesítő'!A:E, 5, FALSE), "") -> 2016 | F6: TRUE
A7: 6 | B7: A hős útja... | C7: =IFERROR(VLOOKUP(B7, 'Filmösszesítő'!A:E, 2, FALSE), "") -> 0.88 | D7: =IFERROR(VLOOKUP(B7, 'Filmösszesítő'!A:E, 4, FALSE), "") -> https://youtu.be/ZjxZlqWpILs | E7: =IFERROR(VLOOKUP(B7, 'Filmösszesítő'!A:E, 5, FALSE), "") -> 2019 | F7: TRUE
A8: 7 | B8: Jó ok a távozásra | C8: =IFERROR(VLOOKUP(B8, 'Filmösszesítő'!A:E, 2, FALSE), "") -> 13.2 | D8: =IFERROR(VLOOKUP(B8, 'Filmösszesítő'!A:E, 4, FALSE), "") -> https://youtu.be/78qHkmMnRnA | E8: =IFERROR(VLOOKUP(B8, 'Filmösszesítő'!A:E, 5, FALSE), "") -> 2019 | F8: TRUE
A9: 8 | B9: Akherón ...és mi lett a pandával? | C9: =IFERROR(VLOOKUP(B9, 'Filmösszesítő'!A:E, 2, FALSE), "") -> 12 | D9: =IFERROR(VLOOKUP(B9, 'Filmösszesítő'!A:E, 4, FALSE), "") -> https://youtu.be/_qTjQ7OeDrc | E9: =IFERROR(VLOOKUP(B9, 'Filmösszesítő'!A:E, 5, FALSE), "") -> 2021 | F9: TRUE
A10: 9 | B10: A varázsló halála | C10: =IFERROR(VLOOKUP(B10, 'Filmösszesítő'!A:E, 2, FALSE), "") -> 1.98 | D10: =IFERROR(VLOOKUP(B10, 'Filmösszesítő'!A:E, 4, FALSE), "") -> https://youtu.be/srPUdQ6Il7o | E10: =IFERROR(VLOOKUP(B10, 'Filmösszesítő'!A:E, 5, FALSE), "") -> 2016 | F10: TRUE
C11: =IFERROR(VLOOKUP(B11, 'Filmösszesítő'!A:E, 2, FALSE), "") | D11: =IFERROR(VLOOKUP(B11, 'Filmösszesítő'!A:E, 4, FALSE), "") | E11: =IFERROR(VLOOKUP(B11, 'Filmösszesítő'!A:E, 5, FALSE), "") | F11: FALSE
C12: =IFERROR(VLOOKUP(B12, 'Filmösszesítő'!A:E, 2, FALSE), "") | D12: =IFERROR(VLOOKUP(B12, 'Filmösszesítő'!A:E, 4, FALSE), "") | E12: =IFERROR(VLOOKUP(B12, 'Filmösszesítő'!A:E, 5, FALSE), "") | F12: FALSE
C13: =IFERROR(VLOOKUP(B13, 'Filmösszesítő'!A:E, 2, FALSE), "") | D13: =IFERROR(VLOOKUP(B13, 'Filmösszesítő'!A:E, 4, FALSE), "") | E13: =IFERROR(VLOOKUP(B13, 'Filmösszesítő'!A:E, 5, FALSE), "") | F13: FALSE
C14: =IFERROR(VLOOKUP(B14, 'Filmösszesítő'!A:E, 2, FALSE), "") | D14: =IFERROR(VLOOKUP(B14, 'Filmösszesítő'!A:E, 4, FALSE), "") | E14: =IFERROR(VLOOKUP(B14, 'Filmösszesítő'!A:E, 5, FALSE), "") | F14: FALSE
C15: =IFERROR(VLOOKUP(B15, 'Filmösszesítő'!A:E, 2, FALSE), "") | D15: =IFERROR(VLOOKUP(B15, 'Filmösszesítő'!A:E, 4, FALSE), "") | E15: =IFERROR(VLOOKUP(B15, 'Filmösszesítő'!A:E, 5, FALSE), "") | F15: FALSE

Sheet Fordulatok (Ricsi)
A1: Sorrend | B1: Cím | C1: Játékidő | D1: Link | E1: Év | F1: Újrarenderelve és mentve
A2: 1 | B2: Asomik | C2: =IFERROR(VLOOKUP(B2, 'Filmösszesítő'!A:E, 2, FALSE), "") -> 0.72 | D2: =IFERROR(VLOOKUP(B2, 'Filmösszesítő'!A:E, 4, FALSE), "") -> https://youtu.be/s1KhAeIctOw | E2: =IFERROR(VLOOKUP(B2, 'Filmösszesítő'!A:E, 5, FALSE), "") -> 2021 | F2: TRUE
A3: 2 | B3: Phish | C3: =IFERROR(VLOOKUP(B3, 'Filmösszesítő'!A:E, 2, FALSE), "") -> 7.75 | D3: =IFERROR(VLOOKUP(B3, 'Filmösszesítő'!A:E, 4, FALSE), "") -> https://youtu.be/dLq1gBb8lSc | E3: =IFERROR(VLOOKUP(B3, 'Filmösszesítő'!A:E, 5, FALSE), "") -> 2016 | F3: TRUE
A4: 3 | B4: Ki ez a sok művész? | C4: =IFERROR(VLOOKUP(B4, 'Filmösszesítő'!A:E, 2, FALSE), "") -> 25.8 | D4: =IFERROR(VLOOKUP(B4, 'Filmösszesítő'!A:E, 4, FALSE), "") -> https://youtu.be/093OOQEkEfU | E4: =IFERROR(VLOOKUP(B4, 'Filmösszesítő'!A:E, 5, FALSE), "") -> 2023 | F4: TRUE
A5: 4 | B5: Aratás | C5: =IFERROR(VLOOKUP(B5, 'Filmösszesítő'!A:E, 2, FALSE), "") -> 30.28 | D5: =IFERROR(VLOOKUP(B5, 'Filmösszesítő'!A:E, 4, FALSE), "") -> https://youtu.be/k5C0P4FN7WQ | E5: =IFERROR(VLOOKUP(B5, 'Filmösszesítő'!A:E, 5, FALSE), "") -> 2022 | F5: TRUE
A6: 5 | B6: The Minimum Clearance Outline | C6: =IFERROR(VLOOKUP(B6, 'Filmösszesítő'!A:E, 2, FALSE), "") -> 8 | D6: =IFERROR(VLOOKUP(B6, 'Filmösszesítő'!A:E, 4, FALSE), "") -> https://youtu.be/nK5TWRSkJrQ | E6: =IFERROR(VLOOKUP(B6, 'Filmösszesítő'!A:E, 5, FALSE), "") -> 2017 | F6: TRUE
A7: 6 | B7: Kezdetben volt a tett | C7: =IFERROR(VLOOKUP(B7, 'Filmösszesítő'!A:E, 2, FALSE), "") -> 3.76 | D7: =IFERROR(VLOOKUP(B7, 'Filmösszesítő'!A:E, 4, FALSE), "") -> https://youtu.be/0PxBSRa3yVs | E7: =IFERROR(VLOOKUP(B7, 'Filmösszesítő'!A:E, 5, FALSE), "") -> 2016 | F7: TRUE
C8: =IFERROR(VLOOKUP(B8, 'Filmösszesítő'!A:E, 2, FALSE), "") | D8: =IFERROR(VLOOKUP(B8, 'Filmösszesítő'!A:E, 4, FALSE), "") | E8: =IFERROR(VLOOKUP(B8, 'Filmösszesítő'!A:E, 5, FALSE), "") | F8: FALSE
C9: =IFERROR(VLOOKUP(B9, 'Filmösszesítő'!A:E, 2, FALSE), "") | D9: =IFERROR(VLOOKUP(B9, 'Filmösszesítő'!A:E, 4, FALSE), "") | E9: =IFERROR(VLOOKUP(B9, 'Filmösszesítő'!A:E, 5, FALSE), "") | F9: FALSE
C10: =IFERROR(VLOOKUP(B10, 'Filmösszesítő'!A:E, 2, FALSE), "") | D10: =IFERROR(VLOOKUP(B10, 'Filmösszesítő'!A:E, 4, FALSE), "") | E10: =IFERROR(VLOOKUP(B10, 'Filmösszesítő'!A:E, 5, FALSE), "") | F10: FALSE
C11: =IFERROR(VLOOKUP(B11, 'Filmösszesítő'!A:E, 2, FALSE), "") | D11: =IFERROR(VLOOKUP(B11, 'Filmösszesítő'!A:E, 4, FALSE), "") | E11: =IFERROR(VLOOKUP(B11, 'Filmösszesítő'!A:E, 5, FALSE), "") | F11: FALSE
C12: =IFERROR(VLOOKUP(B12, 'Filmösszesítő'!A:E, 2, FALSE), "") | D12: =IFERROR(VLOOKUP(B12, 'Filmösszesítő'!A:E, 4, FALSE), "") | E12: =IFERROR(VLOOKUP(B12, 'Filmösszesítő'!A:E, 5, FALSE), "") | F12: FALSE
C13: =IFERROR(VLOOKUP(B13, 'Filmösszesítő'!A:E, 2, FALSE), "") | D13: =IFERROR(VLOOKUP(B13, 'Filmösszesítő'!A:E, 4, FALSE), "") | E13: =IFERROR(VLOOKUP(B13, 'Filmösszesítő'!A:E, 5, FALSE), "") | F13: FALSE

Sheet Projektek (Matyi)
A1: Sorrend | B1: Cím | C1: Játékidő | D1: Link | E1: Év | F1: Újrarenderelve és mentve
A2: 1 | B2: Silence in Bjordall | C2: =IFERROR(VLOOKUP(B2, 'Filmösszesítő'!A:E, 2, FALSE), "") -> 1.05 | D2: =IFERROR(VLOOKUP(B2, 'Filmösszesítő'!A:E, 4, FALSE), "") -> https://youtu.be/QQkATp3ZrNE | E2: =IFERROR(VLOOKUP(B2, 'Filmösszesítő'!A:E, 5, FALSE), "") -> 2021 | F2: TRUE
A3: 2 | B3: Három fehér ló | C3: =IFERROR(VLOOKUP(B3, 'Filmösszesítő'!A:E, 2, FALSE), "") -> 3.96 | D3: =IFERROR(VLOOKUP(B3, 'Filmösszesítő'!A:E, 4, FALSE), "") -> https://youtu.be/fF1MVz1zWrE | E3: =IFERROR(VLOOKUP(B3, 'Filmösszesítő'!A:E, 5, FALSE), "") -> 2018 | F3: TRUE | G3: =SUM(Matyi[Játékidő]) -> 66.25
A4: 3 | B4: Kenopsia, opia, lachesism | C4: =IFERROR(VLOOKUP(B4, 'Filmösszesítő'!A:E, 2, FALSE), "") -> 5.92 | D4: =IFERROR(VLOOKUP(B4, 'Filmösszesítő'!A:E, 4, FALSE), "") -> https://youtu.be/Bs1tHvCRx8E | E4: =IFERROR(VLOOKUP(B4, 'Filmösszesítő'!A:E, 5, FALSE), "") -> 2018 | F4: TRUE
A5: 4 | B5: Mr A, Mr K, a Pápa, Izom Tibor és az elnyomottak | C5: =IFERROR(VLOOKUP(B5, 'Filmösszesítő'!A:E, 2, FALSE), "") -> 5.2 | D5: =IFERROR(VLOOKUP(B5, 'Filmösszesítő'!A:E, 4, FALSE), "") -> https://youtu.be/opjXJhNPBO8 | E5: =IFERROR(VLOOKUP(B5, 'Filmösszesítő'!A:E, 5, FALSE), "") -> 2018 | F5: TRUE
A6: 5 | B6: 4 szoba | C6: =IFERROR(VLOOKUP(B6, 'Filmösszesítő'!A:E, 2, FALSE), "") -> 10 | D6: =IFERROR(VLOOKUP(B6, 'Filmösszesítő'!A:E, 4, FALSE), "") -> TBA | E6: =IFERROR(VLOOKUP(B6, 'Filmösszesítő'!A:E, 5, FALSE), "") -> 2025 | F6: TRUE
A7: 6 | B7: Jószándék | C7: =IFERROR(VLOOKUP(B7, 'Filmösszesítő'!A:E, 2, FALSE), "") -> 5.5 | D7: =IFERROR(VLOOKUP(B7, 'Filmösszesítő'!A:E, 4, FALSE), "") -> https://www.youtube.com/watch?v=NwJ8VgWiHeU | E7: =IFERROR(VLOOKUP(B7, 'Filmösszesítő'!A:E, 5, FALSE), "") -> 2024 | F7: TRUE
A8: 7 | B8: Da Capo | C8: =IFERROR(VLOOKUP(B8, 'Filmösszesítő'!A:E, 2, FALSE), "") -> 5 | D8: =IFERROR(VLOOKUP(B8, 'Filmösszesítő'!A:E, 4, FALSE), "") -> https://youtu.be/JpRKm48n0n0?si=bVzJQbK98ZJ70QqI | E8: =IFERROR(VLOOKUP(B8, 'Filmösszesítő'!A:E, 5, FALSE), "") -> 2018 | F8: TRUE
A9: 8 | B9: Hétköznapi szuperhősök (és hogy miért utáljuk őket) | C9: =IFERROR(VLOOKUP(B9, 'Filmösszesítő'!A:E, 2, FALSE), "") -> 29.62 | D9: =IFERROR(VLOOKUP(B9, 'Filmösszesítő'!A:E, 4, FALSE), "") -> https://youtu.be/ZCSH9qDzpOI | E9: =IFERROR(VLOOKUP(B9, 'Filmösszesítő'!A:E, 5, FALSE), "") -> 2020 | F9: TRUE
C10: =IFERROR(VLOOKUP(B10, 'Filmösszesítő'!A:E, 2, FALSE), "") | D10: =IFERROR(VLOOKUP(B10, 'Filmösszesítő'!A:E, 4, FALSE), "") | E10: =IFERROR(VLOOKUP(B10, 'Filmösszesítő'!A:E, 5, FALSE), "") | F10: FALSE
C11: =IFERROR(VLOOKUP(B11, 'Filmösszesítő'!A:E, 2, FALSE), "") | D11: =IFERROR(VLOOKUP(B11, 'Filmösszesítő'!A:E, 4, FALSE), "") | E11: =IFERROR(VLOOKUP(B11, 'Filmösszesítő'!A:E, 5, FALSE), "") | F11: FALSE
C12: =IFERROR(VLOOKUP(B12, 'Filmösszesítő'!A:E, 2, FALSE), "") | D12: =IFERROR(VLOOKUP(B12, 'Filmösszesítő'!A:E, 4, FALSE), "") | E12: =IFERROR(VLOOKUP(B12, 'Filmösszesítő'!A:E, 5, FALSE), "") | F12: FALSE
C13: =IFERROR(VLOOKUP(B13, 'Filmösszesítő'!A:E, 2, FALSE), "") | D13: =IFERROR(VLOOKUP(B13, 'Filmösszesítő'!A:E, 4, FALSE), "") | E13: =IFERROR(VLOOKUP(B13, 'Filmösszesítő'!A:E, 5, FALSE), "") | F13: FALSE
C14: =IFERROR(VLOOKUP(B14, 'Filmösszesítő'!A:E, 2, FALSE), "") | D14: =IFERROR(VLOOKUP(B14, 'Filmösszesítő'!A:E, 4, FALSE), "") | E14: =IFERROR(VLOOKUP(B14, 'Filmösszesítő'!A:E, 5, FALSE), "") | F14: FALSE
C15: =IFERROR(VLOOKUP(B15, 'Filmösszesítő'!A:E, 2, FALSE), "") | D15: =IFERROR(VLOOKUP(B15, 'Filmösszesítő'!A:E, 4, FALSE), "") | E15: =IFERROR(VLOOKUP(B15, 'Filmösszesítő'!A:E, 5, FALSE), "") | F15: FALSE

Sheet Sötét oldal (Marci)
A1: Sorrend | B1: Cím | C1: Játékidő | D1: Link | E1: Év | F1: Újrarenderelve és mentve
A2: 1 | B2: Greetings from Bjordall | C2: =IFERROR(VLOOKUP(B2, 'Filmösszesítő'!A:E, 2, FALSE), "") -> 1.07 | D2: =IFERROR(VLOOKUP(B2, 'Filmösszesítő'!A:E, 4, FALSE), "") -> https://youtu.be/dgyIO9-bp0g | E2: =IFERROR(VLOOKUP(B2, 'Filmösszesítő'!A:E, 5, FALSE), "") -> 2021 | F2: TRUE
A3: 2 | B3: Biztos, hogy tűzálló | C3: =IFERROR(VLOOKUP(B3, 'Filmösszesítő'!A:E, 2, FALSE), "") -> 3.43 | D3: =IFERROR(VLOOKUP(B3, 'Filmösszesítő'!A:E, 4, FALSE), "") -> https://youtu.be/7Zik7dNAwwU | E3: =IFERROR(VLOOKUP(B3, 'Filmösszesítő'!A:E, 5, FALSE), "") -> 2018 | F3: TRUE
A4: 3 | B4: Holnap | C4: =IFERROR(VLOOKUP(B4, 'Filmösszesítő'!A:E, 2, FALSE), "") -> 12.1 | D4: =IFERROR(VLOOKUP(B4, 'Filmösszesítő'!A:E, 4, FALSE), "") -> https://youtu.be/OgBC-vPL0W8 | E4: =IFERROR(VLOOKUP(B4, 'Filmösszesítő'!A:E, 5, FALSE), "") -> 2024 | F4: TRUE
A5: 4 | B5: Fényszennyezés | C5: =IFERROR(VLOOKUP(B5, 'Filmösszesítő'!A:E, 2, FALSE), "") -> 5.65 | D5: =IFERROR(VLOOKUP(B5, 'Filmösszesítő'!A:E, 4, FALSE), "") -> https://youtu.be/UCVhZ09MsD4 | E5: =IFERROR(VLOOKUP(B5, 'Filmösszesítő'!A:E, 5, FALSE), "") -> 2017 | F5: TRUE
A6: 5 | B6: Piroska és a Farkas | C6: =IFERROR(VLOOKUP(B6, 'Filmösszesítő'!A:E, 2, FALSE), "") -> 16.78 | D6: =IFERROR(VLOOKUP(B6, 'Filmösszesítő'!A:E, 4, FALSE), "") -> https://youtu.be/oOY_ZimZMC0 | E6: =IFERROR(VLOOKUP(B6, 'Filmösszesítő'!A:E, 5, FALSE), "") -> 2019 | F6: TRUE
A7: 6 | B7: Ördögszekér | C7: =IFERROR(VLOOKUP(B7, 'Filmösszesítő'!A:E, 2, FALSE), "") -> 25 | D7: =IFERROR(VLOOKUP(B7, 'Filmösszesítő'!A:E, 4, FALSE), "") -> https://youtu.be/DZnKJDzESfI | E7: =IFERROR(VLOOKUP(B7, 'Filmösszesítő'!A:E, 5, FALSE), "") -> 2025 | F7: TRUE
C8: =IFERROR(VLOOKUP(B8, 'Filmösszesítő'!A:E, 2, FALSE), "") | D8: =IFERROR(VLOOKUP(B8, 'Filmösszesítő'!A:E, 4, FALSE), "") | E8: =IFERROR(VLOOKUP(B8, 'Filmösszesítő'!A:E, 5, FALSE), "") | F8: FALSE
C9: =IFERROR(VLOOKUP(B9, 'Filmösszesítő'!A:E, 2, FALSE), "") | D9: =IFERROR(VLOOKUP(B9, 'Filmösszesítő'!A:E, 4, FALSE), "") | E9: =IFERROR(VLOOKUP(B9, 'Filmösszesítő'!A:E, 5, FALSE), "") | F9: FALSE
C10: =IFERROR(VLOOKUP(B10, 'Filmösszesítő'!A:E, 2, FALSE), "") | D10: =IFERROR(VLOOKUP(B10, 'Filmösszesítő'!A:E, 4, FALSE), "") | E10: =IFERROR(VLOOKUP(B10, 'Filmösszesítő'!A:E, 5, FALSE), "") | F10: FALSE
C11: =IFERROR(VLOOKUP(B11, 'Filmösszesítő'!A:E, 2, FALSE), "") | D11: =IFERROR(VLOOKUP(B11, 'Filmösszesítő'!A:E, 4, FALSE), "") | E11: =IFERROR(VLOOKUP(B11, 'Filmösszesítő'!A:E, 5, FALSE), "") | F11: FALSE
C12: =IFERROR(VLOOKUP(B12, 'Filmösszesítő'!A:E, 2, FALSE), "") | D12: =IFERROR(VLOOKUP(B12, 'Filmösszesítő'!A:E, 4, FALSE), "") | E12: =IFERROR(VLOOKUP(B12, 'Filmösszesítő'!A:E, 5, FALSE), "") | F12: FALSE
C13: =IFERROR(VLOOKUP(B13, 'Filmösszesítő'!A:E, 2, FALSE), "") | D13: =IFERROR(VLOOKUP(B13, 'Filmösszesítő'!A:E, 4, FALSE), "") | E13: =IFERROR(VLOOKUP(B13, 'Filmösszesítő'!A:E, 5, FALSE), "") | F13: FALSE
C14: =IFERROR(VLOOKUP(B14, 'Filmösszesítő'!A:E, 2, FALSE), "") | D14: =IFERROR(VLOOKUP(B14, 'Filmösszesítő'!A:E, 4, FALSE), "") | E14: =IFERROR(VLOOKUP(B14, 'Filmösszesítő'!A:E, 5, FALSE), "") | F14: FALSE
C15: =IFERROR(VLOOKUP(B15, 'Filmösszesítő'!A:E, 2, FALSE), "") | D15: =IFERROR(VLOOKUP(B15, 'Filmösszesítő'!A:E, 4, FALSE), "") | E15: =IFERROR(VLOOKUP(B15, 'Filmösszesítő'!A:E, 5, FALSE), "") | F15: FALSE

Sheet Személyes köszöntők
B1: Első élmények | C1: Mit jelent a Nocturnal Dog | D1: Mit emelnék ki a blokkból
A2: Ádám | B2: Volt egy Aranyelmés csoportom, kiöregedéshez közekedvén közölték, szeretnének tovább járni, de van két kérésük: ne iskolaépületben legyünk, és egy szót se mondjak biológiáról. Mivel a kiöregedő aranyelmések úgy is mindig sok kérdést felvetettek (nem lehetne tovább is foglalkozni velük valamilyen más formában), kitaláltuk, hogy az 1000tea pincéjében megváltjuk a világot szombat délutánonként. Némi drámapedagagógia már belekerült ezekbe az alkalmakba, aztán amikor szóba jött Campbell, és a "monomyth" elmélet, kitaláltuk, hogy csináljunk egy filmet. Megcsináltuk, élveztük. Következő ősszel indult az első filmes csoportunk Ricsivel. | C2: Elsősorban egy nagyon furcsa szociális szövedék, amit pár tucat, nagyon különböző gyerek, fiatal és felnőtt alkot. És kísérletezünk, hogy minél több módon meséljünk, elemezzünk, kérdezzünk. Meggyöződésem, hogy ez művészet. Vállaltan amatőr, útkereső, sokszor naiv, ügyetlen, sőt kifejezetten béna, de az alapján, amit megértettem arról, mit jelent az, hogy művészet, ez az. | D2: A "How to make a remake" tökéletes példája szakkörünk legmélyebb dilemmájának: remek hangulatú tábor, kreatív folyamat, remek hangulat, teljes bevonódás, flow, zseniális, minden hatáton túl zseniális egy hét együttlét, szórakozás, és rengeteg munka. A film pedig...egy nagyon-nagyon szerethető emlék, egy remek "insider joke". Ha azonban a hipotetikus vagy akár valós külső közönség szemszögéből próbálom nézni, tartok tőle, nagyon kevés részlet érthető, érvényes, érdekes, ha egyáltalán bármi. És ez feszegeti a kérdést -identitáskérdést - tulajdon éppen mit is akarunk, és mit is tudunk ezzel a csoporttal. Mert első igazi "ident" filmünkkel, a 1435-el letettük a tantuszt valami mellett, ami azóta is kísért, már nem úgy érvényes, de még mindig erősen meghatározó. Nagyon tudjuk, mit nem akarunk csinálni, sejtjük, hogy mit szeretnénk, és próbálunk rájönni, hogyan.
A3: Matyi | B3: Egyetemről sokat jártam át az 1000tea teaházba és sokszor amikor betévedtem azt mondták, hogy "Ádámék lent vannak" - mint hogy tudták, hogy ismerjük egymást. Néha lenéztem a pincébe és akkor láttam az első foglalkozást. 2018 nyarán kérdezett meg Ádám, hogy van-e kedvem foglalkozásokat tartani vele. | C3: Egy hely, ahol remélhetőleg mindenki becsatornázhatja a kreatív energiáit valamilyen alkotásba. Ahol lehet és érdemes magas és alacsony művészetről beszélni. Ahol a világ minden dolga érdekes, tűnjön bármilyen távolinak vagy jelentéktelennek kívülről. Ahol próbálunk módokat biztosítani arra, hogy mindenki olyannak élhesse meg magát, ami neki a legjobb. | D3: Amire elkészül egy film a Nocturnal Dog foglalkozásokon nagyon sok munkafázison esik át. Egy ötletből, játékból, történetből indítunk és először a végtelenségig tágítjuk az alkotás szövetét, majd összeszűkítjük akkorára, hogy egy külső befogadónak érthető és - esetleg - élvezhető legyen. Viszont így sok olyan dolog, amit mi nagyon szerettünk, értékesnek tartunk, ott marad a foglalkozásokon. Azok a filmek, amik a nevem alatt futó 'Projektek' blokkban vannak, kicsit túlmutatnak azon, amit filmre sikerült vinni. Nekem kedves alkotások, amik mögött sokkal több van, mint amit elsőre megnézésre észre lehet venni.
A4: Marci | B4: Én 2014 végén öregedtem ki az Aranyelméből, ahol azelőtt leginkább Ádám foglalkozásaira jártam. Ez után jött a felvetés Ádám részéről, hogy volna e kedvem továbbra is foglalkozásokra járni, egy másik témában illetve helyszínen. Így mentem el 2016 szeptemberében az első filmes fogallkozásomra az 100TEA pincéjébe. | C4: Ha a Noctrunal Dogra gondolok, valami olyan kép jut eszembe (mondhatnám, hogy cinematic photography), ahol egy adag gyerek mindenféle babzsákon, meg kanapén heverve mogyorót eszik, mindenkit fura kellékek vesznek körül és a kép közepén meg 1-2 ember, abbl az egyik biztosan egy nagydarab szakállas, a másik mikor ki. Sokszor nagy a káosz, érthetetlen a folyamat, kicsit amatőr a forgatás, az egész tűnhet egy katyvasznak. Ez a szüzsé. Az amit egy szemlélő láthat belőle. A fabula, a világ ami mögötte van az viszont sokkal több. Az alkotás folyamata önmagában érték, az pedig, hogy eközben egy közösség is kovácsolódik méginkább. A Nocturnal Dog legnagyobb ereje ez, hogy egy nagyon karakteres hangulaton keresztül olyan embereket tud egy közösséggé formálni, akik soha nem találkoznának egyébként, ráadásul a megteremti a lehetőséget arra, hogy közösen alkotva egymás mellett fejlődjünk. | D4: Kár lenne tagadni, hogy a filmjeink között nem hemzsegnek a vígjátékok, komédiák. A sötét, olykor nyomasztó, néha csak misztikus légkör az alkotások többségénél jelen megtalálható. Ugyanakkor ennek számtalan arca van. A 'Sötétség' blokk néhány nagyon különböző filmet gyűjt egy csokorba, amik valahogy mind egy bűnnel teli, esetleg apokaliptikus világot mutatnak be. Vagy a szereplők maguk sötétek, de legalább ilyen gyakran az őket körülvevő világ, esetleg a sorsuk, feladatuk. Ugyanakkor mindegyik film nagyon máshogy közelíti ezt meg, más módszerekkel, más hangnemben, más műfajban mutatja be az érme sötét oldalát és ezzel más-más megoldást is kínálnak saját démonaink legyőzésére.
A5: Ricsi | B5: 2015-ben, amikor újra felvettük a fonalat egymással Ádámmal, az Aranyelme Tehetséggondozó Egyesület táborain gondolkodva sokszor szóba került, hogy nagyon szeretnénk nagyobbaknak szóló, drámás-filmes szakkört is csinálni. Ekkor mondta Ádám, hogy ő valami hasonlóba már belekezdett az akkor épp kiöregedő csoportjával. Kolonics Benedek, Szepesi Dániel, Koródi Flóra, Hódosi Kriszti és még páran fogékonyaknak tűntek az ötletre. | C5: Egy olyan művészeti alkotóközösségként képzelem el magunkat, ahol mindenféle formális kurrikulumon túl a saját ösvényeinken keresztül találjuk meg a válaszainkat művészetelméleti, elbeszéléselméleti, film- és montázselméleti, és egyéb terület kérdéseire. És önző vagy nem önző, ez nem csupán a résztvevőkről szól, hanem rólunk is, akik szervezik és tartják ezeket az alkalmakat, összefogják a projekteket, hiszen legalább annyit tanulunk mi is, mint a becsatalkozó diákjaink, gyerekek. Így ezt tényleg nehéz leírni máshogy: a Nocturnal Dog egy kreatív közösség. | D5: Az általam kurált blokk a "Fordulatok" nevet kapta, amely a viszonylag könnyed koncepcióm szerint a csoport innovációit, újításait ragadná meg. Minden film, amely itt kapott helyet, miután végeztünk velük, és először nézhettem végig izgatottan a gyerekekkel az utolsó renderelést követően, azt éreztem, hogy "igen, megérkeztünk, sikerült állítanunk valamit a filmmel, sikerült építenünk valamit". Az Aratás közülük az egyik legfrissebb ilyen élmény volt: a képeink Nocturnal Dogos képek, a dialógusainkat csodálatosan formálták magukra a színészeink, a történetet pedig már ezer éve el akartuk mesélni, de csak ebben a bizonyos táborban álltak így a csillagok. Nem beszélve arról, hogy Hildur Guðnadóttir menedzsmentje is belement a sok zaklatásom után, hogy hadd használjuk legálisan a művész zenéjét soundtrackként.

Sheet Szereplők
A1: Vezetéknév | B1: Keresztnév | C1: Filmek
A2: Ács | B2: Gergő | C2: The Minimum Clearance Outline | D2: Piroska
A3: Aradi | B3: Matyi | C3: Kenopsia, Opia, Lachesism | D3: Jó Ok a Távozásra | E3: 1435 MM | F3: How to Make a Remake | G3: Hétköznapi szuperhősök | H3: Aeronautica a 21sz.-ban. | I3: De capo
A4: Balics | B4: Andris | C4: Aratás | D4: Ki ez a sok művész? | E4: 4 szoba | F4: Drámaország | G4: Jószándék | H4: Kiterítenek úgy is...
A5: Barbély | B5: Milos | C5: Drámaország | D5: Aratás
A6: Bethlenfalvy | B6: Lőrinc | C6: Három Fehér Ló | D6: Jó Ok a Távozásra | E6: 1435 MM | F6: Hétköznapi szuperhősök | G6: Aeronautica a 21sz.-ban. | H6: De capo
A7: Bethlenfalvy | B7: Ambrus | C7: 1435 MM
A8: Blazsovszky | B8: Ádi | C8: Aratás | D8: 4 szoba | E8: Jószándék | F8: Kiterítenek úgy is...
A9: Borsodi (Máté) | B9: Borsi | C9: 4 szoba | D9: Jószándék | E9: Kiterítenek úgy is...
A10: Chogyelka | B10: Andris | C10: Aratás | D10: Ki ez a sok művész? | E10: 4 szoba | F10: Jószándék | G10: Kiterítenek úgy is...
A11: Chogyelka | B11: Tomi | C11: 4 szoba
A12: Dénes | B12: Andris | C12: Hétköznapi szuperhősök
A13: Dolhay | B13: Csongi | C13: Biztos, hogy Tűzálló | D13: Mr A, Mr K, a Pápa, Izom Tibor és az elnyomottak | E13: How to Make a Remake
A14: Dolhay | B14: Tündi | C14: Aratás
A15: Erdődi | B15: Sándor | C15: Holnap | D15: 4 szoba | E15: Jószándék | F15: Kiterítenek úgy is...
A16: Gajdátsy | B16: Márk | C16: Három Fehér Ló | D16: Jó Ok a Távozásra
A17: Hódosi | B17: Kriszti | C17: How to Make a Remake | D17: Phish
A18: Kajzinger | B18: Panka | C18: Biztos, hogy Tűzálló | D18: Piroska | E18: Jó Ok a Távozásra | F18: Mr A, Mr K, a Pápa, Izom Tibor és az elnyomottak | G18: Aratás | H18: The Minimum Clearance Outline | I18: How to Make a Remake | J18: Drámaország | K18: Hétköznapi szuperhősök
A19: Kajzinger | B19: Vince | C19: Kenopsia, Opia, Lachesism | D19: Jó Ok a Távozásra | E19: 1435 MM | F19: How to Make a Remake | G19: Phish | H19: Hétköznapi szuperhősök | I19: Aeronautica a 21sz.-ban. | J19: De capo
A20: Koródi | B20: Flóra | C20: How to Make a Remake
A21: L | B21: Andris | C21: 4 szoba
A22: Makara | B22: Samu | C22: Kenopsia, Opia, Lachesism
A23: Mónos | B23: Peti | C23: How to Make a Remake
A24: Nagy | B24: Balázs | C24: Aratás | D24: Holnap | E24: Drámaország | F24: Jószándék
A25: Názer | B25: Panni | C25: Honap | D25: Aratás | E25: Ki ez a sok művész? | F25: Drámaország | G25: Kiterítenek úgy is...
A26: Ondruss | B26: Gergő | C26: Jó Ok a Távozásra | D26: The Minimum Clearance Outline | E26: Phish
A27: Ottrok | B27: Vera | C27: Hétköznapi szuperhősök
A28: Rapai | B28: Peti | C28: Biztos, hogy Tűzálló | D28: Piroska | E28: Jó Ok a Távozásra | F28: Mr A, Mr K, a Pápa, Izom Tibor és az elnyomottak | G28: Aratás | H28: Holnap | I28: Hétköznapi szuperhősök
A29: Réthly | B29: Ármin | C29: Biztos, hogy Tűzálló | D29: Piroska | E29: Jó Ok a Távozásra | F29: Mr A, Mr K, a Pápa, Izom Tibor és az elnyomottak | G29: Hétköznapi szuperhősök
A30: Révész | B30: Zsuzsi | C30: Kenopsia, Opia, Lachesism | D30: The Minimum Clearance Outline | E30: How to Make a Remake | F30: Phish | G30: De capo
A31: Révész-Heuer | B31: Jakab | C31: Aratás | D31: Ki ez a sok művész? | E31: 4 szoba | F31: Drámaország | G31: Jószándék | H31: Kiterítenek úgy is... | I31: Holnap
A32: Svékus | B32: Ádám | C32: Aratás | D32: Ki ez a sok művész? | E32: Drámaország
A33: Szabó | B33: Villő | C33: 4 szoba
A34: Székács | B34: Gúz | C34: Kenopsia, Opia, Lachesism | D34: Jó Ok a Távozásra | E34: Akherón ...és mi lett a pandával? | F34: Aratás | G34: How to Make a Remake | H34: Drámaország | I34: Jószándék | J34: Kiterítenek úgy is...
A35: Szöllősi | B35: Zsuzsi | C35: Aratás | D35: Ki ez a sok művész? | E35: Drámaország
A36: Szuromi-Kovács | B36: Barci | C36: Ki ez a sok művész? | D36: 4 szoba
A37: Tarján | B37: Terka | C37: Három Fehér Ló | D37: Jó Ok a Távozásra | E37: Aratás | F37: The Minimum Clearance Outline | G37: How to Make a Remake | H37: Drámaország | I37: Hétköznapi szuperhősök
A38: Tarján | B38: Ferkó | C38: Akherón ...és mi lett a pandával? | D38: Jó Ok a Távozásra | E38: Aratás | F38: Drámaország | G38: Hétköznapi szuperhősök | H38: Jószándék | I38: Kiterítenek úgy is...
A39: Tarján | B39: Berci | C39: Jó Ok a Távozásra | D39: Aratás | E39: How to Make a Remake | F39: Drámaország | G39: Hétköznapi szuperhősök
A40: Tarján | B40: Mici | C40: Aratás | D40: Ki ez a sok művész? | E40: 4 szoba | F40: Kiterítenek úgy is...
...

Sheet Visszajelzések
A1: Jön | B1: Talán | C1: Nem | D1: Nincs visszajelzés
A2: Jakab | B2: Balázs | C2: Berci
A3: CAndris | B3: Ádi | C3: Ferkó
A4: Svékus Ádám | B4: Zoli | C4: Terka
A5: Pancsi | B5: O. Gergő | C5: Mici
A6: Panka | B6: Samu | C6: H. Kriszti
A7: Vince | B7: O. Vera | C7: Gúz
A8: CTomi
A9: BAndris
A10: Ádi
